Workbook

Sheet SỔ_THU_CHI
A1: Mã phiếu | B1: Ngày giờ | C1: Loại | D1: Mã khách hàng | E1: Tên khách hàng | F1: Mã hóa đơn | G1: Số tiền | H1: Ghi chú

Sheet DANH_MỤC
A1: Điều hướng nhanh
A2: Khách hàng | B2: KHÁCH HÀNG
A3: Hàng hóa | B3: Hàng Q302
A4: Hóa đơn chi tiết | B4: CHI TIẾT HÓA ĐƠN
A5: Công nợ | B5: CÔNG NỢ THEO HÓA ĐƠN
A6: Mẫu hóa đơn | B6: LÊN HÓA ĐƠN
A7: Sheet thao tác | B7: TẠO_HÓA_ĐƠN / PHIẾU_THU_CHI

Sheet PHIẾU_THU_CHI
A1: PHIẾU THU / CHI
A2: Loại | B2: receipt
A3: Mã khách hàng
A4: Mã hóa đơn
A5: Số tiền | B5: 0
A6: Phương thức | B6: Tiền mặt
A7: Ghi chú
A8: Chạy macro CreateVoucherFromForm

Sheet TẠO_HÓA_ĐƠN
A1: TẠO HÓA ĐƠN
A2: Mã khách hàng
A3: Tên khách hàng
A4: Ghi chú
A5: Mã SP | B5: Số lượng
A10: Chạy macro CreateInvoiceFromForm sau khi nhập xong

Sheet DASHBOARD
A1: 302 STORE MANAGER
A2: Tổng khách hàng | B2: =COUNTA('KHÁCH HÀNG'!B:B)-1 -> 946
A3: Tổng hàng hóa | B3: =COUNTA('Hàng Q302'!C:C)-1 -> 909
A4: Tổng hóa đơn | B4: =COUNTA('CÔNG NỢ THEO HÓA ĐƠN'!A:A)-1 -> 2
A5: Tổng công nợ | B5: =SUM('CÔNG NỢ THEO HÓA ĐƠN'!G:G)-SUM('CÔNG NỢ THEO HÓA ĐƠN'!H:H) -> 3988000
A6: Tổng doanh số | B6: =SUM('KHÁCH HÀNG'!H:H) -> 45451378
A7: Mở sheet MENU để điều hướng
A8: Bản này dùng kèm module VBA trong thư mục vba

Sheet MENU
A1: 302 STORE MANAGER VBA
A2: Mục | B2: Sheet | C2: Ghi chú
A3: Khách hàng | B3: KHÁCH HÀNG | C3: Dữ liệu khách
A4: Hàng hóa | B4: Hàng Q302 | C4: Danh mục bán hàng
A5: Hóa đơn | B5: CHI TIẾT HÓA ĐƠN | C5: Chi tiết bán hàng
A6: Công nợ | B6: CÔNG NỢ THEO HÓA ĐƠN | C6: Theo dõi phải thu
A7: Mẫu hóa đơn | B7: LÊN HÓA ĐƠN | C7: In/xem mẫu
A8: Hướng dẫn | B8: MENU | C8: Sheet điều hướng

Sheet LÊN HÓA ĐƠN
B1: Quầy 302 Hapulico
B2: Địa chỉ: Tòa nhà Hapulico, Thanh Xuân, Hà Nội
B3: Hotline: 0918377022
A5: HÓA ĐƠN BÁN HÀNG
A6: HD0029
A9: Mã khách hàng | B9: {=IFERROR(INDEX('KHÁCH HÀNG'!B:B, MATCH(B10, 'KHÁCH HÀNG'!C:C, 0)), "")} -> KH302775123
A10: Khách hàng: | B10: =IFERROR(__xludf.DUMMYFUNCTION("IFERROR(INDEX(FILTER('KHÁCH HÀNG'!C2:C996, ISNUMBER(SEARCH(C10, 'KHÁCH HÀNG'!C2:C996))), 1), """")"),"C Liên Nghệ An") -> C Liên Nghệ An | C10: C Liên Nghệ An
A11: Địa chỉ: | B11: {=IFERROR(INDEX('KHÁCH HÀNG'!E:E, MATCH(TRIM(B9), 'KHÁCH HÀNG'!B:B, 0)), "")} -> Số 425 đường Phủ Quỳ(gần Vincom),Thị Xã Thái Hòa,Nghệ An
A12: SĐT: | B12: {=IFERROR(INDEX('KHÁCH HÀNG'!D:D, MATCH(TRIM(B9), 'KHÁCH HÀNG'!B:B, 0))&"", "")} -> 984126238
A14: STT | B14: MÃ HÀNG | C14: TÊN HÀNG | D14: HÌNH ẢNH | E14: SỐ LƯỢNG | F14: ĐƠN GIÁ | G14: THÀNH TIỀN
A15: 1 | B15: {=IFERROR(INDEX('HÀNG HÓA'!C:C, MATCH(C15, 'HÀNG HÓA'!D:D, 0)), "")} -> SP64856123 | C15: Pharkavita extra hộp 60 viên | D15: {=IFERROR(INDEX('HÀNG HÓA'!E:E, MATCH(C15, 'HÀNG HÓA'!D:D, 0)), "")} -> 0 | E15: 2 | F15: {=IFERROR(INDEX('HÀNG HÓA'!F:F, MATCH(C15, 'HÀNG HÓA'!D:D, 0)), "")} -> 42000 | G15: =F15*E15 -> 84000
A16: 2 | B16: {=IFERROR(INDEX('HÀNG HÓA'!C:C, MATCH(C16, 'HÀNG HÓA'!D:D, 0)), "")} -> SP64856118 | C16: Men vi sinh TGS-Bio lacto hộp 20 ống 10ml | D16: {=IFERROR(INDEX('HÀNG HÓA'!E:E, MATCH(C16, 'HÀNG HÓA'!D:D, 0)), "")} -> 0 | E16: 5 | F16: {=IFERROR(INDEX('HÀNG HÓA'!F:F, MATCH(C16, 'HÀNG HÓA'!D:D, 0)), "")} -> 55000 | G16: =E16*F16 -> 275000
A17: 3 | B17: {=IFERROR(INDEX('HÀNG HÓA'!C:C, MATCH(C17, 'HÀNG HÓA'!D:D, 0)), "")} -> SP64856123 | C17: Pharkavita extra hộp 60 viên | D17: {=IFERROR(INDEX('HÀNG HÓA'!E:E, MATCH(C17, 'HÀNG HÓA'!D:D, 0)), "")} -> 0 | E17: 4 | F17: {=IFERROR(INDEX('HÀNG HÓA'!F:F, MATCH(C17, 'HÀNG HÓA'!D:D, 0)), "")} -> 42000 | G17: =E17*F17 -> 168000
A18: 4 | D18: {=IFERROR(INDEX('HÀNG HÓA'!E:E, MATCH(C18, 'HÀNG HÓA'!D:D, 0)), "")} | G18: =E18*F18 -> 0
A19: 5 | D19: {=IFERROR(INDEX('HÀNG HÓA'!E:E, MATCH(C19, 'HÀNG HÓA'!D:D, 0)), "")} | G19: =E19*F19 -> 0
A20: 6 | B20: {=IFERROR(INDEX('HÀNG HÓA'!C:C, MATCH(C20, 'HÀNG HÓA'!D:D, 0)), "")} | D20: {=IFERROR(INDEX('HÀNG HÓA'!E:E, MATCH(C20, 'HÀNG HÓA'!D:D, 0)), "")} | F20: {=IFERROR(INDEX('HÀNG HÓA'!F:F, MATCH(C20, 'HÀNG HÓA'!D:D, 0)), "")} | G20: =E20*F20 -> #VALUE!
A21: 7 | B21: {=IFERROR(INDEX('HÀNG HÓA'!C:C, MATCH(C21, 'HÀNG HÓA'!D:D, 0)), "")} | D21: {=IFERROR(INDEX('HÀNG HÓA'!E:E, MATCH(C21, 'HÀNG HÓA'!D:D, 0)), "")} | F21: {=IFERROR(INDEX('HÀNG HÓA'!F:F, MATCH(C21, 'HÀNG HÓA'!D:D, 0)), "")} | G21: =E21*F21 -> #VALUE!
A22: Tổng cộng: | G22: =SUM(G15:G21) -> #VALUE!
A23: Giảm giá:
A24: Thu khác:
A25: Nợ đơn cũ:
A26: Hàng mua hộ:
A27: Số tiền đã trả | G27: 0
A28: TỔNG THANH TOÁN: | G28: =G22-G23+G24+G25+G26-G27 -> #VALUE!
A32: KHÔNG NHẬN TRẢ HÀNG TRỪ TRƯỜNG HỢP LỖI TỪ NHÀ SẢN XUẤT VÀ QUẦY
A34: Ghi chú: | B34: {=IFERROR(INDEX('KHÁCH HÀNG'!F:F, MATCH(B9, 'KHÁCH HÀNG'!B:B, 0)), "")} -> CHUYỂN KHOẢN TRƯỚC XE BỒ CÂU CƯỚC KHÁCH TRẢ
A35: Quý khách vui lòng quay video khi nhận hàng để giải quyết khiếu nại nếu phát sinh.
A37: Mọi khiếu nại xin phản hồi trong vòng 7 ngày kể từ ngày nhận hàng.
A38: Sau thời gian này Quầy xin phép không giải quyết.

Sheet SỬA HÓA ĐƠN
A1: Quầy 302 Hapulico
A2: Địa chỉ: Tòa nhà Hapulico, Thanh Xuân, Hà Nội
A3: Hotline: 0855558886
A5: HÓA ĐƠN BÁN HÀNG
A6: HD0026
A9: Mã khách hàng | B9: KH302775136
A10: Khách hàng: | B10: A Định 1089 (N)
A11: Địa chỉ: | B11: {=IFERROR(INDEX('KHÁCH HÀNG'!E:E, MATCH(TRIM(B9), 'KHÁCH HÀNG'!B:B, 0)), "")} -> 785 TRƯƠNG ĐỊNH
A12: SĐT: | B12: {=IFERROR(INDEX('KHÁCH HÀNG'!D:D, MATCH(TRIM(B9), 'KHÁCH HÀNG'!B:B, 0))&"", "")} -> 914530918
A14: STT | B14: MÃ HÀNG | C14: TÊN HÀNG | D14: HÌNH ẢNH | E14: SỐ LƯỢNG | F14: ĐƠN GIÁ | G14: THÀNH TIỀN
B15: SP64856122
A22: Tổng cộng:
A23: Giảm giá:
A24: Thu khác:
A25: Nợ đơn cũ:
A26: Hàng mua hộ:
A27: Số tiền đã trả
A28: TỔNG THANH TOÁN:
A30: Tổng thanh toán bằng chữ: .......................................
A32: KHÔNG NHẬN TRẢ HÀNG TRỪ TRƯỜNG HỢP LỖI TỪ NHÀ SẢN XUẤT VÀ QUẦY
A34: Ghi chú:
A35: Quý khách vui lòng quay video khi nhận hàng để giải quyết khiếu nại nếu phát sinh.
A37: Mọi khiếu nại xin phản hồi trong vòng 7 ngày kể từ ngày nhận hàng.
A38: Sau thời gian này Quầy xin phép không giải quyết.

Sheet CHI TIẾT HÓA ĐƠN
A1: Mã hóa đơn | B1: Ngày giờ | C1: Mã khách hàng | D1: Tên Khách hàng | E1: Mã Sản phẩm | F1: Tên sản phẩm | G1: Số lượng | H1: Đơn giá | I1: Thành tiền | J1: Tổng tiền hóa đơn
A2: HD0027 | B2: 46126.442 | C2: KH302775137 | D2: NT Phượng Chín Yên Bái | E2: SP64856009 | F2: Cà Gai Leo tam thất - xạ đen_h50v_Rostex date 2/2028 ( ) | G2: 30 | H2: 52000 | I2: 1560000 | J2: 2714000
A3: HD0027 | B3: 46126.442 | C3: KH302775137 | D3: NT Phượng Chín Yên Bái | E3: SP64856070 | F3: 12B ginseng linzhi hộp 100 viên ( ) | G3: 5 | H3: 50000 | I3: 250000
A4: HD0027 | B4: 46126.442 | C4: KH302775137 | D4: NT Phượng Chín Yên Bái | E4: SP64856014 | F4: Biotin Nutriday Hàn Quốc hàng nhập khẩu ( ) | G4: 4 | H4: 226000 | I4: 904000
A5: HD0028 | B5: 46126.665 | C5: KH302775123 | D5: C Liên Nghệ An | E5: SP64856064 | F5: Đại tràng mộc hoa trắng lọ 30 viên ( ) | G5: 2 | H5: 60000 | I5: 120000 | J5: 1274000
A6: HD0028 | B6: 46126.665 | C6: KH302775123 | D6: C Liên Nghệ An | E6: SP64856070 | F6: 12B ginseng linzhi hộp 100 viên ( ) | G6: 5 | H6: 50000 | I6: 250000
A7: HD0028 | B7: 46126.665 | C7: KH302775123 | D7: C Liên Nghệ An | E7: SP64856014 | F7: Biotin Nutriday Hàn Quốc hàng nhập khẩu ( ) | G7: 4 | H7: 226000 | I7: 904000

Sheet CÔNG NỢ THEO HÓA ĐƠN
A1: Mã Hóa đơn | B1: Ngày | C1: Mã khách hàng | D1: Tên khách | E1: SĐT | F1: Ghi chú | G1: Khách cần trả | H1: Khách đã trả
A2: HD0027 | B2: 46126.442 | C2: KH302775137 | D2: NT Phượng Chín Yên Bái | E2: 779309888 | F2: GHTK THU COD FREESHIP | G2: 2714000 | H2: 0
A3: HD0028 | B3: 46126.665 | C3: KH302775123 | D3: C Liên Nghệ An | E3: 984126238 | F3: CHUYỂN KHOẢN TRƯỚC XE BỒ CÂU CƯỚC KHÁCH TRẢ | G3: 1274000 | H3: 0

Sheet KHÁCH HÀNG
A1: STT | B1: Mã khách hàng | C1: Tên khách hàng | D1: Điện thoại | E1: Địa chỉ | F1: Ghi chú | G1: Nợ cần thu hiện tại | H1: Tổng bán
A2: 1 | B2: KH302775137 | C2: NT Phượng Chín Yên Bái | D2: 779309888 | E2: thôn Liên Hiệp,Minh Quân,Trấn Yên,Yên Bái | F2: GHTK THU COD FREESHIP | G2: 4134000 | H2: 4134000
A3: 2 | B3: KH302775136 | C3: C Thanh Vui Nam Định | D3: 914530918 | E3: 785 TRƯƠNG ĐỊNH | F3: CHUYỂN KHOẢN TRƯỚC SHIP GẦN :XE A BÌNH 785 TRƯƠNG ĐỊNH(0912375710) 12H CHẠY FREESHIP | G3: 0 | H3: 10,200,000
A4: 3 | B4: KH302775135 | C4: Phạm văn duy | D4: 982004578 | E4: Thôn phạm xá | H4: 0
A5: 4 | B5: KH302775134 | C5: A Quyết Hưng Yên | D5: 989334611 | F5: XE PHƯƠNG LINH THU HỘ | G5: 0 | H5: 2,590,000
A6: 5 | B6: KH302775133 | C6: Đàm Thị Như Thi( Quầy Thuốc Đoàn Thi) | D6: 388653414 | E6: Thôn cây hồng xã chi lăng tỉnh lạng sơn | G6: 7940000 | H6: 7940000
A7: 6 | B7: KH302775132 | C7: C hiền | D7: 986140581 | E7: Nghĩa vũ dục tú đông anh hà nội | H7: 0
A8: 7 | B8: KH302775131 | C8: Quầy thuốc Quang Thương | D8: 978794813 | E8: Xóm 1 | H8: 0
A9: 8 | B9: KH302775130 | C9: Bích Huyền | D9: 763396463 | E9: Trường mầm non Phú Long ấp 4 Rạch Gừa xã Phú Long huyện Bình Đại tỉnh Bến Tre | H9: 0
A10: 9 | B10: KH302775129 | C10: Như Phụng | D10: 385424789 | E10: Đại lý Phụng Loan, ấp Cà Dâm | H10: 0
A11: 10 | B11: KH302775128 | C11: Vy Vy | D11: 338531802 | E11: Tổ 6 khu vực 6 ( ngay cầu thồ lồ cũ ) | H11: 0
A12: 11 | B12: KH302775127 | C12: khách le | G12: 0 | H12: 0
A13: 12 | B13: KH302775126 | C13: Ngavq | D13: 939388686 | E13: Ngõ 31 hoàng cầu ngách 34 số nhà A7 tập thể bộ công an | H13: 0
A14: 13 | B14: p | C14: yoiuoiu | H14: 0
A15: 14 | B15: KH302775125 | C15: Tiệp | D15: 942787805 | E15: Cty dfzin đường n4 khu công nghiệp hòa xá | G15: 0 | H15: 0
A16: 15 | B16: KH302775124 | C16: tiên | D16: 347850426 | E16: phù yên | H16: 0
A17: 16 | B17: KH302775123 | C17: C Liên Nghệ An | D17: 984126238 | E17: Số 425 đường Phủ Quỳ(gần Vincom),Thị Xã Thái Hòa,Nghệ An | F17: CHUYỂN KHOẢN TRƯỚC XE BỒ CÂU CƯỚC KHÁCH TRẢ | G17: 1274000 | H17: 1274000
A18: 17 | B18: KH302775122 | C18: Nguyễn Trọng Nguyễn | D18: 941252562 | E18: 55, kênh 7, ấp Phủ Thờ | H18: 0
A19: 18 | B19: KH302775121 | C19: C Ly Hậu Giang | D19: 0789 539 737 | E19: 29b Nguyễn Thị Minh Khai,Phường IV,thành phố Vị Thanh,Hậu Giang | F19: GHTK THU COD KHÔNG CHO ĐƠN HÀNG TIÊM ĐÓNG CẨN THẬN | G19: 0 | H19: 3,069,000
A20: 19 | B20: KH302775120 | C20: tóc đẹp ngọc khải | D20: 964405148 | E20: 55 đường Nguyễn Thị Định | H20: 0
A21: 20 | B21: KH302775119 | C21: Hải Nguyễn | D21: 989809993 | E21: Khu phố ngọc khám phường gia đông | G21: 0 | H21: 0
A22: 21 | B22: KH302775118 | C22: Lăng Thị Hệ | D22: 961895128 | E22: Căn 1806, Toà CT2, Chung cư Iris Garden, P. Trần Hữu Dực , Cầu Diễn , Nam Từ Liêm , HN | H22: 0
A23: 22 | B23: KH302775117 | C23: Hoài Trần | D23: 326792288 | E23: Số 2 ngõ 100 Tân Khai | H23: 0
A24: 23 | B24: KH302775116 | C24: ân | D24: 902750998 | E24: 124/3/1 tan chánh hiệp 35 kp37 | H24: 0
A25: 24 | B25: KH302775115 | C25: A nghĩa Phú Quốc | D25: 345366148 | E25: KHU PHỐ 6 NHÀ TRỌ THẢO LINH THÀNH PHỐ PHÚ QUỐC DƯƠNG ĐÔNG | F25: GHTK CHUYỂN KHOẢN TRƯỚC CƯỚC KHÁCH TRẢ | G25: 0 | H25: 14,100,000
A26: 25 | B26: KH302775114 | C26: Vũ | D26: 333048683 | E26: 16 Tân Thới Nhì 35, Dân Thắng 1 | H26: 0
A27: 26 | B27: KH302775113 | C27: Mai Đình Chương | D27: 939600838 | E27: 180/5 Song Hành,Trung Chánh, Bà Điểm, TpHCM | H27: 0
A28: 27 | B28: KH302775112 | C28: Ân | D28: 818888021 | E28: chùa pháp hoa | H28: 0
A29: 28 | B29: KH302775111 | C29: DAT | D29: 344231642 | E29: ÂP RẠCH TRÚC Xã TRUNG THÀNH | H29: 0
A30: 29 | B30: KH302775110 | C30: Đinh Phong | D30: 939467258 | E30: 384/40/9 Lý Thái Tổ | H30: 0
A31: 30 | B31: KH302775109 | C31: C Hương Phú Quốc | D31: 344757637 | E31: Bún quậy kiến xây khu phố 9,phường dương đông,đặc khu Phú Quốc,Kiên Giang | F31: CK TRƯỚC GHTK CƯỚC KHÁCH TRẢ | G31: 0 | H31: 41,700,000
A32: 31 | B32: KH302775108 | C32: Vo Thuong | D32: 913656729 | E32: Đồng chúp | H32: 0
A33: 32 | B33: KH302775107 | C33: Lợi | D33: 375513446 | E33: Thọ nghĩa , phước nghĩa,tuy phước ,bình đinh | H33: 0
A34: 33 | B34: KH302775106 | C34: Mỹ Tiên Phú Yên | D34: 395665268 | E34: khu phố Phú Thọ 2,phường Hòa Hiệp Trung,thị xã Đông Hòa,Phú Yên | F34: GHTK CHUYỂN KHOẢN CƯỚC KHÁCH TRẢ | G34: 0 | H34: 1,410,000
A35: 34 | B35: KH302775105 | C35: C Hòa Mê Linh | D35: 977509564 | E35: Xóm 6, hoàng kim, mê linh, Hà Nội | F35: THU HỘ XE LỢI HÀ | G35: 0 | H35: 3,925,000
A36: 35 | B36: KH302775104 | C36: Lê Thanh NHÂN | D36: 372178598 | E36: Chợ bình phú | H36: 0
A37: 36 | B37: KH302775103 | C37: Phương Thảo Nghệ An | D37: 394251789 | E37: số 81 Nguyễn Trãi,Tân Kỳ,Nghệ An | F37: GHTK | G37: 0 | H37: 1,677,000
A38: 37 | B38: KH302775102 | C38: C Mai Nam Định | D38: 399274151 | E38: xóm Tân TIến,Giao Tân,Giao Thủy,Nam Định | F38: GHTK | G38: 0 | H38: 3,950,000
A39: 38 | B39: KH302775101 | C39: An Nguyên | D39: 784228785 | E39: 26/18/8 Trường chinh | H39: 0
A40: 39 | B40: KH302775100 | C40: Tran Nam | D40: 942561245 | E40: 151 nguyễn đức cảnh | H40: 0
...

Sheet HÀNG HÓA
A1: STT | B1: Nhóm hàng(3 Cấp) | C1: Mã hàng | D1: Tên hàng | E1: Hình ảnh (url1,url2...) | F1: Gía bán | G1: Tồn kho | H1: Tồn kho
A2: 1948 | B2: TRÁNH THAI - PHỤ KHOA | C2: Q30227032372 | D2: " ( 10/2024 )Sadetabs Gramon Uruguay (hộp 12 viên đặt) " | G2: https://cdn2-retail-images.kiotviet.vn/2026/03/31/giabaopharma/eddf4fe23d9542c4a3795556878f55d2.jpg | H2: 29885
A3: 3256 | B3: THUỐC | C3: Q302665378 | D3: " (Chai 30ml) Motilium Domperidon Janssen " | G3: #NUM! | H3: 29745
A4: 3255 | B4: THUỐC | C4: Q302774830 | D4: " (Chai 60ml) Motilium Domperidon Janssen " | G4: https://cdn2-retail-images.kiotviet.vn/2026/03/31/giabaopharma/5f52ab13ad864281bb1ff46064eac7ce.jpg,https://cdn2-retail-images.kiotviet.vn/2026/03/31/giabaopharma/1ba022e70e0548d99452df74cc18ab74.jpeg,https://cdn2-retail-images.kiotviet.vn/2026/03/31/giabaopharma/f63c2250d31d4aac82e373246f5f4caf.jpeg | H4: 30000
A5: 3458 | B5: TPCN" | C5: Q302947384 | D5: " (Dạng gói) Siro Ho Cảm Ích Nhi Nam Dược (Hộp 30 gói x 5ml) " | G5: https://cdn2-retail-images.kiotviet.vn/2026/03/31/giabaopharma/9e84645c0b3943138abebeab4de07e6a.jpeg,https://cdn2-retail-images.kiotviet.vn/2026/03/31/giabaopharma/bff85634b6644da3b37dca1f28951814.jpeg,https://cdn2-retail-images.kiotviet.vn/2026/03/31/giabaopharma/5120623e656749a3a50c17527b517d1c.jpeg | H5: 30000
A6: 3457 | B6: TPCN" | C6: Q302984930 | D6: " (Dạng lọ) Siro Ho Cảm Ích Nhi Nam Dược (Hộp 1 lọ x 90ml) " | G6: https://cdn2-retail-images.kiotviet.vn/2026/03/30/giabaopharma/3634d7fbf8c34f7ea19b5c42f985c783.jpg | H6: 30000
A7: 483 | B7: TIM MẠCH - HUYẾT ÁP | C7: Q3023052327 | D7: " (date 10/24) Kavasdin Amlodipine 5mg Khánh Hòa (hộp10 vỉ x 10 viên) " | G7: https://cdn2-retail-images.kiotviet.vn/2026/03/31/giabaopharma/ff7c164d962d4cbdb36dcb336d1ad0ea.jpg | H7: 1
A8: 2946 | B8: TÁC DỤNG TRÊN RUỘT | C8: Q3027032399 | D8: " (date 10/24) Zaclid Esomeprazol 20mg Mediplantex (hộp 3 vỉ x 10 viên) " | G8: https://cdn2-retail-images.kiotviet.vn/2026/03/24/giabaopharma/8ed7cef3dda040cd9450a4a52b208afe.jpg | H8: 998
A9: 2091 | B9: TIM MẠCH - HUYẾT ÁP | C9: Q3022403112 | D9: " (date 11/2025) Amlor 5mg Pfizer Úc( hộp 3 vỉ x 10 viên nén) " | G9: https://cdn2-retail-images.kiotviet.vn/2026/03/19/giabaopharma/2834f92c00a144b8b65b3adf95477f84.jpg | H9: 1
A10: 1635 | B10: THUỐC | C10: Q302000001010 | D10: " (date 11/24) Telfor Fexpfenadine 180mg DHG Hậu Giang (hộp 2 vỉ x 10 viên nén ) " | G10: https://cdn2-retail-images.kiotviet.vn/2026/03/18/giabaopharma/71e43f3190ae408e8c70dd5b12c61968.jpg | H10: 980
A11: 2706 | B11: TRÁNH THAI - PHỤ KHOA | C11: Q30213032354 | D11: " (Date 11/24) Vastad Stella (hộp 1 vỉ x 10 viên đặt âm đạo) " | G11: https://cdn2-retail-images.kiotviet.vn/2026/03/09/giabaopharma/eda3c2a5da9c4587a5a284a0d9e3f2d6.jpg | H11: 995
A12: 936 | B12: CHỐNG VIÊM | C12: Q3021952381 | D12: " (date 4/2025) Methylprednisolon 16mg Vidipha (hộp 3 vỉ x 10 viên nén) " | G12: https://cdn2-retail-images.kiotviet.vn/2026/03/05/giabaopharma/cdf424f0d2314a88be85b9f8b27a9b1c.jpg | H12: 79
A13: 2096 | B13: TIM MẠCH - HUYẾT ÁP | C13: Q3022403107 | D13: " (date 6/2025) Amloda Amlodipine 5mg Z120 ( hộp 10 vỉ x 10 viên nang) " | G13: https://cdn2-retail-images.kiotviet.vn/2026/03/05/giabaopharma/c4f34e08f7924ed4b01081bd35dca45a.jpg | H13: 96
A14: 2048 | B14: NÃO - THẦN KINH | C14: Q3022403207 | D14: " (Date 6/2025) Arcalion 200mg Servier Pháp( lọ 30 viên nén ) " | G14: https://cdn2-retail-images.kiotviet.vn/2026/03/02/giabaopharma/ec81c3e1e2524a45ada28d99b31145ba.jpg | H14: 966
A15: 2645 | B15: NÃO - THẦN KINH | C15: Q302130323167 | D15: " (date 7/26)Trihex Trihexyphenidyl hydroclrid 2mg Đà Nẵng (hộp 5 vỉ x 20 viên nén) " | G15: https://cdn2-retail-images.kiotviet.vn/2026/02/09/giabaopharma/f13b277034f343c7a7acb1c676275a79.jpg | H15: 890
... A196: 2117 | B196: DA LIỄU | C196: Q3022403035 | D196: " Alvextra kem dưỡng da Tanida( lọ 50g ) " | G196: https://cdn2-retail-images.kiotviet.vn/2024/09/30/giabaopharma/e8e62f4012c345d49ba1ac58294881da.jpg | H196: 0
A197: 2116 | B197: TRÁNH THAI - PHỤ KHOA | C197: Q3022403036 | D197: " Amariston Mifepristone 10mg tránh thai INVE ( hộp 1 viên nén) " | H197: 0
A198: 2115 | B198: HO - LONG ĐỜM | C198: Q3022403037 | D198: " Ambroco Ambroxol 15mg/5ml United( lọ 30ml) " | G198: https://cdn2-retail-images.kiotviet.vn/2024/09/24/giabaopharma/c4d5a86ceb59444f9eb61adf422619bb.png | H198: 999
A199: 2112 | B199: HO - LONG ĐỜM | C199: Q3022403042 | D199: " Ambron Ambroxol 30mg Vacopharm ( lọ 100 viên nang ) " | G199: https://cdn2-retail-images.kiotviet.vn/2025/02/18/giabaopharma/fe41572708804163950971fa8ca8f8e2.jpg | H199: 0
A200: 2113 | B200: HO - LONG ĐỜM | C200: Q3022403041 | D200: " Ambron Ambroxol 30mg Vacopharm( hộp 50 gói x 1g) " | G200: https://cdn2-retail-images.kiotviet.vn/2025/02/25/giabaopharma/fb9d6459b03046dabfb089b5d25263d9.jpg | H200: 1
A201: 2114 | B201: HO - LONG ĐỜM | C201: Q3022403040 | D201: " Ambron Ambroxol 30mg xanh dương Vacopharm ( hộp 10 vỉ x 10 viên nang) " | G201: https://cdn2-retail-images.kiotviet.vn/2025/02/25/giabaopharma/fec53d8c89804b949f9027a7613eb52b.jpg | H201: 0
A202: 216 | B202: HO - LONG ĐỜM | C202: SP648524 | D202: " Ambron tab vacopharm 10 vỉ 10 viên" | G202: https://cdn2-retail-images.kiotviet.vn/giabaopharma/278ecaf346b742bea1376d44e67f763f.jpg | H202: 0
A203: 2111 | B203: HO - LONG ĐỜM | C203: Q3022403043 | D203: " Ambroxol 15mg/5ml Đà Nẵng( lọ 60ml ) " | G203: https://cdn2-retail-images.kiotviet.vn/2025/02/25/giabaopharma/a86faeefd85a43a0832d5eddf100f8cc.jpg | H203: 972
A204: 2109 | B204: HO - LONG ĐỜM | C204: Q3022403045 | D204: " Ambroxol 30mg Boston ( hộp 3 vỉ x 10 viên nén) " | G204: https://cdn2-retail-images.kiotviet.vn/giabaopharma/c0dcb75ca68b4eb5b53c226728c28573.jpg | H204: 0
A205: 2110 | B205: HO - LONG ĐỜM | C205: Q3022403044 | D205: " Ambroxol 30mg Domesco( hộp 10 vỉ x 10 viên nang) " | G205: https://cdn2-retail-images.kiotviet.vn/giabaopharma/41ded983f07441f2bcdcddde51759a71.jpg | H205: 0
A206: 2108 | B206: HO - LONG ĐỜM | C206: Q3022403046 | D206: " Ambroxol 30mg NIC ( lọ 200 viên nén) " | G206: https://cdn2-retail-images.kiotviet.vn/2025/02/25/giabaopharma/82c9d8c038454de4a620199bcf15a6ce.jpg | H206: 0
A207: 2107 | B207: DA LIỄU | C207: Q3022403047 | D207: " Amcinol Paste Mekophar ( lốc 10 tuýp 5g ) " | G207: https://cdn2-retail-images.kiotviet.vn/2025/02/26/giabaopharma/799a3a9d915e4edfa9b4987e3052cf29.jpg | H207: 430
A208: 2106 | B208: CẢM CÚM - VIÊM XOANG | C208: Q3022403048 | D208: " Ameflu Day Time + C cảm cúm OPV ( hộp 10 vỉ x 10 viên nén) " | G208: https://cdn-images.kiotviet.vn/giabaopharma/fbbebdff226547c1940ce169952f5e14.png | H208: 888
A209: 2105 | B209: CẢM CÚM - VIÊM XOANG | C209: Q3022403049 | D209: " Ameflu Day Time cảm cúm OPV( hộp 10 vỉ x 10 viên nén) " | G209: https://cdn-images.kiotviet.vn/giabaopharma/8663983cfcb64834a74261574a613e6e.png | H209: 900
... A221: 2092 | B221: TIM MẠCH - HUYẾT ÁP | C221: Q3022403111 | D221: " Amlodipine EG 5mg Pymepharco( hộp 3 vỉ x 10 viên nang) " | G221: https://cdn2-retail-images.kiotviet.vn/giabaopharma/090509eb1c5a4b7193190350630be6b8.jpg,https://cdn2-retail-images.kiotviet.vn/giabaopharma/5aba60d8bd1a4348ba1c60d1103022ab.jpg,https://cdn2-retail-images.kiotviet.vn/giabaopharma/3e81bd19cc5d47f5a7e596ae9d39a4d9.jpg,https://cdn2-retail-images.kiotviet.vn/giabaopharma/15f99b729f6049f3a59544e90805a44a.jpg,https://cdn2-retail-images.kiotviet.vn/giabaopharma/abb4391a19b549a9b1b8b372a8d4a59c.jpg | H221: 9.851
A222: 2089 | B222: KHÁNG SINH - KHÁNG VIRUS | C222: Q3022403114 | D222: " Amoxicillin 250mg Domesco( lọ 100 viên ngậm) " | G222: https://cdn-images.kiotviet.vn/2025/08/14/giabaopharma/25076de3fe004befbcb7407fee6a5a52.jpg | H222: ########
A223: 3447 | B223: KHÁNG SINH - KHÁNG VIRUS | C223: Q302574684 | D223: " Amoxicillin 250mg Mekophar (Hộp 30 gói x 2,5g) " | G223: https://cdn2-retail-images.kiotviet.vn/giabaopharma/e9c265d8e71349ec8b1ed4c14040dcbe.jpg | H223: 0
A224: 2090 | B224: KHÁNG SINH - KHÁNG VIRUS | C224: Q3022403113 | D224: " Amoxicillin 250mg Mekophar(hộp 10 vỉ x 10 viên nang) " | G224: https://cdn2-retail-images.kiotviet.vn/giabaopharma/1801bb0c2ea54428a64ea9c40b58c51a.jpg | H224: 10
A225: 2088 | B225: KHÁNG SINH - KHÁNG VIRUS | C225: Q3022403115 | D225: " Amoxicillin 500mg Domesco( hộp 10 vỉ x 10 viên nang) " | G225: https://cdn-images.kiotviet.vn/giabaopharma/63320416cc504723b5242c7220caacd5.jpg | H225: 0
A226: 2087 | B226: KHÁNG SINH - KHÁNG VIRUS | C226: Q3022403116 | D226: " Amoxicillin 500mg Mekophar( hộp 10 vỉ x 10 viên nang ) " | G226: https://cdn2-retail-images.kiotviet.vn/giabaopharma/ad55eaa97e2a4a3db07de6818094be77.jpg,https://cdn2-retail-images.kiotviet.vn/giabaopharma/30a950a13890403291cf2fe14b33c695.jpg,https://cdn-images.kiotviet.vn/giabaopharma/9606c3cf6bd74da28b2a9abf9f3838ae.jpg,https://cdn2-retail-images.kiotviet.vn/giabaopharma/5823351e7a9c463fbc1ef9157e954ceb.jpg,https://cdn2-retail-images.kiotviet.vn/giabaopharma/d69e810ac9ce4741a4e401a3193655c9.jpg | H226: 0
A227: 3448 | B227: KHÁNG SINH - KHÁNG VIRUS | C227: Q302667489 | D227: " Amoxicillin 500mg Pharbaco (Hộp 10 vỉ x 10 viên nang) " | G227: https://cdn2-retail-images.kiotviet.vn/giabaopharma/847684efd96c4a6abffb7f9cc06ba53a.jpg | H227: 0
A228: 2086 | B228: KHÁNG SINH - KHÁNG VIRUS | C228: Q3022403117 | D228: " Amoxicillin 500mg Thanh Hóa( hộp 10 vỉ x 10 viên nang) " | G228: https://cdn2-retail-images.kiotviet.vn/giabaopharma/d5853bcbcc644883b33ffc8bc820859a.jpg | H228: 812
A229: 2085 | B229: KHÁNG SINH - KHÁNG VIRUS | C229: Q3022403118 | D229: " Amoxicillin 500mg TW1 Pharbaco( hộp 10 vỉ x 10 viên nang ) " | G229: https://cdn-images.kiotviet.vn/giabaopharma/eb9eec10858e4d19affc82452da7650b.jpg | H229: 0
A230: 2084 | B230: KHÁNG SINH - KHÁNG VIRUS | C230: Q3022403119 | D230: " Ampicilin 250mg Thanh Hóa( lọ 250 viên nén ) " | G230: https://cdn2-retail-images.kiotviet.vn/giabaopharma/c96516e3bd4449ef8ba79b6c18ad26e7.png | H230: 0
A231: 2083 | B231: KHÁNG SINH - KHÁNG VIRUS | C231: Q3022403120 | D231: " Ampicillin 250mg TW1 Pharbaco( lọ 200 viên nén) " | G231: https://cdn2-retail-images.kiotviet.vn/giabaopharma/62824fbd8dee4bb8976511b0af6da67d.png | H231: 0
...

Sheet Hàng Q302
A1: STT | B1: Nhóm hàng | C1: Mã hàng | D1: Tên hàng | E1: Hình ảnh (url1,url2...) | F1: Giá bán | G1: Tồn kho | H1: Hình ảnh (url1,url2...)
A2: 1 | B2: CẢM CÚM - VIÊM XOANG | C2: SP64856088 | D2: An cold Flu D hộp 100 viên (cảm cúm) | F2: 46,000.0 | G2: 93.0 | H2: https://cdn2-retail-images.kiotviet.vn/2025/10/02/giabaopharma/9f2e7b1dfa624ed68dfc40a0b31dbf38.jpg
A3: 50 | B3: CẢM CÚM - VIÊM XOANG | C3: SP64856076 | D3: Xịt mũi Seesalt Baby Kingphar chai 70ml ( ) | F3: 16,000.0 | G3: 0.0 | H3: https://i.postimg.cc/JnMZHrbC/X-t-n-c-mu-i-bi-n-s-u-Seesalt-Baby-Kingphar-l-m-s-ch-m-i-1-chai-70ml-2.png
A4: 51 | B4: CẢM CÚM - VIÊM XOANG | C4: SP64856075 | D4: Xịt mũi Seesalt Kingphar chai 70ml ( ) | F4: 16,000.0 | G4: 0.0 | H4: https://i.postimg.cc/Dy8sXYbf/X-t-n-c-mu-i-bi-n-s-u-Seesalt-Kingphar-l-m-s-ch-m-i-1-chai-70ml-3.png
A5: 2 | B5: CẢM CÚM - VIÊM XOANG | C5: SP648595 | D5: Đa triệu chứng gói hộp 12 gói ( ) | F5: 42,000.0 | G5: 877.0 | H5: https://cdn2-retail-images.kiotviet.vn/2025/02/13/giabaopharma/7e0b804d613c4f878fd4ab458f3db5ac.jpg
A6: 3 | B6: CHỐNG VIÊM | C6: SP648573 | D6: Sivkort-triamcinolone 80mg tiêm hộp 5 ống *2ml Đài Loan date 6/2027 ( TRIAM SIV ) | F6: 139,000.0 | G6: 138,001.0 | H6: https://cdn2-retail-images.kiotviet.vn/2024/12/19/giabaopharma/d0a6b7d4a147478e8858e361a65fc90a.jpg,https://cdn-images.kiotviet.vn/2024/12/19/giabaopharma/9714c8518c66419fb08c02b7c2a7d6a7.jpg
A7: 4 | B7: CHỐNG VIÊM | C7: SP648560 | D7: date 9/2027 Lisanolonola Triamcinolone Acetonide 80mg/2ml ( H/5 ống x 2ml) ( TRIAM LISA ) | F7: 350,000.0 | G7: 3,532.0 | H7: https://cdn-images.kiotviet.vn/2024/12/09/giabaopharma/aa4d25c9ac934935b34d33e5977ec63f.jpg
A8: 218 | B8: CHỐNG VIÊM | C8: SP648520 | D8: ( date 12/2026) Colcigen colchicine 1mg Celogen ( Hộp 10 vỉ x 10 viên ) ( COL COLCH ) | F8: 48,000.0 | G8: 0.0 | H8: https://cdn-images.kiotviet.vn/giabaopharma/c8537616b8bf4b2b8541f064a499a9a4.jpg
A9: 5 | B9: CHỐNG VIÊM | C9: SP648515 | D9: (Date 10/2026) Boston Methylboston 4mg( Hộp 30 viên) ( METHY 4 ) | F9: 21,000.0 | G9: 10,000.0 | H9: https://cdn2-retail-images.kiotviet.vn/giabaopharma/1801bb0c2ea54428a64ea9c40b58c51a.jpg
A10: 224 | B10: CHỐNG VIÊM | C10: SP648514 | D10: (DATE 7/25) Ibuprofen 400 Umedica ( hộp 10 vỉ x 10 viên) ( IBU UME ) | F10: 31,000.0 | G10: 0.0 | H10: https://cdn-images.kiotviet.vn/giabaopharma/63320416cc504723b5242c7220caacd5.jpg
A11: 236 | B11: CHỐNG VIÊM | C11: SP648499 | D11: (1/26) Panecox-90 Etoricoxib Acme Formulation 90mg (H/ 3 vỉ x 10 viên) ( ETO 90 ) | F11: 51,000.0 | G11: 0.0 | H11: https://cdn-images.kiotviet.vn/giabaopharma/de009112a6044b4e8c4dd91c32a21c41.jpg,https://cdn2-retail-images.kiotviet.vn/giabaopharma/b0be9c5e65b147988e8b5918a7ea33d3.jpg,https://cdn-images.kiotviet.vn/giabaopharma/313a468c311f405198387a25d9d3b3cc.jpg,https://cdn2-retail-images.kiotviet.vn/giabaopharma/e638b1f3207c488d9ddfac570de067ff.jpg,https://cdn2-retail-images.kiotviet.vn/giabaopharma/14433434a7be4482a0e02bb9d653e579.jpg
A12: 269 | B12: CHỐNG VIÊM | C12: Q302281223 | D12: (DateT10/27) Tuýp Vivian Diclofenac Gel BP 30g Lincoln ( DICLO VI ) | F12: 17,000.0 | G12: 0.0 | H12: https://cdn-images.kiotviet.vn/giabaopharma/adc3a78e7e5b4503976f173429370b31.png,https://cdn-images.kiotviet.vn/giabaopharma/9fa484bdd1664c56868d678e86154c67.png,https://cdn-images.kiotviet.vn/giabaopharma/fcc49c655b8e4fd5b065b16bc7266db9.png,https://cdn-images.kiotviet.vn/giabaopharma/e7f3520f986940ae8ced32d7cef84778.png,https://cdn-images.kiotviet.vn/giabaopharma/8d5b7067fd704aa4b81e4520bd76f95a.png
A13: 289 | B13: CHỐNG VIÊM | C13: Q302171023 | D13: (DateT9/24) Alphachymotrypsin Chymotrypsin 4,2mg S.Pharm (Hộp 5 vỉ x 10 viên nén) ( ALPHA CHY ) | F13: 19,000.0 | G13: 0.0 | H13: https://cdn2-retail-images.kiotviet.vn/giabaopharma/28b3a63e256a4b9db33fe6f49a80548c.png
A14: 453 | B14: CHỐNG VIÊM | C14: Q302120923 | D14: (DateT6/26) Meloxicam Tablets 7.5mg Flamingo (Hộp 10 vỉ x 10 viên nén) ( MELO 01 ) | F14: 18,000.0 | G14: 0.0 | H14: https://product.hstatic.net/200000428801/product/20_972e3abf702349a395217070fdbba513.png
A15: 6 | B15: CHỐNG VIÊM | C15: Q30231032385 | D15: Prednison 5mg Robinson (lọ 1000 viên nén) 03/2027 ( PRED RO ) | G15: 899.0 | H15: https://product.hstatic.net/200000428801/product/upload_ce7a8f41df88491ab6bad1ab99a9b163.jpg
A16: 1843 | B16: CHỐNG VIÊM | C16: Q302290323173 | D16: (DateT2/25) Pyclin 150 Clindamycin 150mg Pymepharco (hộp 10 vỉ x 10 viên nang) ( CLIN PY ) | F16: 116,000.0 | G16: 0.0 | H16: https://product.hstatic.net/200000428801/product/21144cdb94064a50af77bb34ef999079_10e7d5650aaa4eb1a18b03ad0705e86c.png
A17: 3573 | B17: CHỐNG VIÊM | C17: Q30200406 | D17: Umeran 75 Umedical Lab Diclofenac Sodium 75mg ( H/10 ống x 3ml) ( DICLO UME ) | F17: 11,000.0 | G17: 0.0 | H17: https://product.hstatic.net/200000428801/product/zalo_screenshot_19_11_2021_639360_58de639c7a1f48f5b9e9787c00bf9f09.png
A18: 3577 | B18: CHỐNG VIÊM | C18: Q30200200 | D18: (Date 3/26) Triamcinolone Flamingo 4mg (H/ 10 vỉ x10 viên) ( TRIAM FLA ) | F18: 53,000.0 | G18: 0.0 | H18: https://product.hstatic.net/200000428801/product/964544e9bcf478aa21e5_e57df4bd23a646d28d009655f4ed5985.jpg
A19: 7 | B19: CHỐNG VIÊM | C19: Q30200086 | D19: (Date 02/27) Triamcinolone Brawn Lab 4mg (H/10 vỉ x 10 viên) ( TRIAM BRA ) | F19: 60,000.0 | G19: 108,877.0 | H19: https://cdn2-retail-images.kiotviet.vn/2025/10/30/giabaopharma/c270c26bab8447dd95909798f87b9cc8.jpg
A20: 3648 | B20: CHỐNG VIÊM | C20: Q30200358 | D20: Preforin Injection Methylprednisolon Myungmoon (H/ 10 lọ bột pha tiêm) ( MRTHY PRE ) | F20: 186,000.0 | G20: 0.0 | H20: https://product.hstatic.net/200000428801/product/bf47feeb1bcad89481db_886af90df7824ef182a91f7a4f26ae3a.jpg
A21: 3676 | B21: CHỐNG VIÊM | C21: Q30200054 | D21: Pamatase methylprednisolone 40mg Hàn Quốc (H/10 ống) ( METHY PAMA ) | F21: 301,000.0 | G21: 0.0 | H21: https://product.hstatic.net/200000428801/product/pamatase_methylprednisolone_sodium_40mg_hop_10_lo_tiem_han_quoc_86a78d99fa4749abb1ead533b948dce9.jpg
A22: 8 | B22: CHỐNG VIÊM | C22: Q30200314 | D22: (9/27) Ospexin cefalexin áo 500mg(vỉ /10v) ( CEFA OSPE ) | F22: 29,500.0 | G22: 999,970.0 | H22: https://product.hstatic.net/200000428801/product/20211211_145447_5e2d590df28e4bf2b4939542f1e104cd.png
A23: 3696 | B23: CHỐNG VIÊM | C23: Q30200188 | D23: (Date 2/28) Notenxic Triamcinolon USP (H/10 vỉ x 10 viên) ( TRIAM NOTEN ) | F23: 47,000.0 | G23: 0.0 | H23: https://cdn1-retail-images.kiotviet.vn/2026/01/15/giabaopharma/2349c757f04047c183cdaa9648a96b7c.jpg
A24: 9 | B24: CHỐNG VIÊM | C24: Q30200244 | D24: Methylprednisolon 16 Khapharco Methylprednisolon 16mg (H/10 vỉ x 10 viên) ( METHY 16 ) | F24: 86,000.0 | G24: 98,494.0 | H24: https://cdn2-retail-images.kiotviet.vn/2026/02/03/giabaopharma/dfb5d3b8805c4e4f86a34bfeb75d8a3a.jpg
A25: 3730 | B25: CHỐNG VIÊM | C25: Q30200084 | D25: (03/27) Metasone Brawn Lab Betamethasone 0.5 mg (H/10 vỉ x 10 viên) ( BETA META ) | F25: 46,000.0 | G25: ######## | H25: https://cdn1-retail-images.kiotviet.vn/2026/01/09/giabaopharma/cb53cf1cc7e948b98317775e37236587.jpg
A26: 10 | B26: CHỐNG VIÊM | C26: Q30200107 | D26: ( Date 08/27) Meloxicam Brawn Lab 7,5mg (H/10 vỉ x 10 viên) ( CELE MIC ) | F26: 22,000.0 | G26: 980,730.0 | H26: https://cdn2-retail-images.kiotviet.vn/2025/12/31/giabaopharma/bd52447d83e947a589f0aea629f61700.jpg
A27: 3887 | B27: CHỐNG VIÊM | C27: Q30200419 | D27: Diclotabs -50 Diclofenac Natri 50mg Axon (H/ 10 vỉ * 10 viên) ( DICLO TAB ) | F27: 20,500.0 | G27: 0.0 | H27: https://product.hstatic.net/200000428801/product/9a026ebaa2b761e938a6_b3f21e3bd1004a3db0315f98464f093a.jpg
... A166: 3995 | B166: HO - LONG ĐỜM | C166: Q30200538 | D166: Bổ phổi Thuymododulin dạng viên (H/ 30 viên) ( Q30200538 ) | F166: 45,000.0 | G166: 0.0 | H166: https://product.hstatic.net/200000428801/product/5eadf94e1013de4d8702_855a6fc93edc4d59bddf9131cfddd3db.png
A167: 3996 | B167: HO - LONG ĐỜM | C167: Q30200575 | D167: Bộ kit Trueline Covid-19 Ag Rapid Test Medicon (H/ 25 bộ) ( Q30200575 ) | G167: 0.0 | H167: https://product.hstatic.net/200000428801/product/truline_44e0cd6ff7f0457f83680700a3d87e96.jpg
A168: 4025 | B168: HO - LONG ĐỜM | C168: Q30200568 | D168: Asthalin Inhaler Cipla ( H/ 1 ống hít) ( ASTHA ) | F168: 64,000.0 | G168: 0.0 | H168: https://product.hstatic.net/200000428801/product/thiet_ke_khong_ten__47__8b5c90b4eb7b4240a9280a91d6187b96.png
A169: 4043 | B169: HO - LONG ĐỜM | C169: Q30200541 | D169: Ambroxol An Thiên 30mg (C/30ml) ( AMBRO AT ) | F169: 23,500.0 | G169: 0.0 | H169: https://product.hstatic.net/200000428801/product/zalo_screenshot_17_11_2021_953653_ce3de0b521484f88a441f02097799bc8.png
A170: 4044 | B170: HO - LONG ĐỜM | C170: Q30200553 | D170: Ambroflam Ambroxol Flamigo 30mg (H/100 viên) ( AMBRO 2 ) | F170: 36,000.0 | G170: 0.0 | H170: https://product.hstatic.net/200000428801/product/thiet_ke_khong_ten__44__fbe6376928a446d3bc36d708004fd6ee.png
A171: 60 | B171: KHÁNG HISTAMIN - DỊ ỨNG | C171: SP64856117 | D171: Amoxicillin 500mg Ấn aurobindo hộ 100 viên | F171: 86,000.0 | G171: 1,000.0 | H171: https://cdn2-retail-images.kiotviet.vn/2026/03/19/giabaopharma/2834f92c00a144b8b65b3adf95477f84.jpg
A172: 61 | B172: KHÁNG HISTAMIN - DỊ ỨNG | C172: SP64856015 | D172: Bostanex siro 30 ml -desloratadine Boston ( DESLORA ) | F172: 30,000.0 | G172: 998.0 | H172: https://cdn2-retail-images.kiotviet.vn/2025/03/28/giabaopharma/b7befa3c0ef84a75ad3e82ab488b999c.jpg
A173: 62 | B173: KHÁNG HISTAMIN - DỊ ỨNG | C173: SP648588 | D173: Colegis siro 60ml ( COLE ) | F173: 37,000.0 | G173: 991.0 | H173: https://cdn2-retail-images.kiotviet.vn/2025/02/06/giabaopharma/aa3b651794ab4fc3bba80effcf1979fa.jpg
A174: 63 | B174: KHÁNG HISTAMIN - DỊ ỨNG | C174: SP648538 | D174: Fexofenadine 180mg US hộp 10 viên ( FEXO 180 ) | F174: 20,000.0 | G174: 972.0 | H174: https://cdn2-retail-images.kiotviet.vn/2025/02/25/giabaopharma/a86faeefd85a43a0832d5eddf100f8cc.jpg
A175: 230 | B175: KHÁNG HISTAMIN - DỊ ỨNG | C175: SP648508 | D175: (DATE 5/25) LORATADINE ATADYN Tablets USP 10mg (Hộp 10x10 Tablets) ( LORA 1 ) | F175: 22,000.0 | G175: 0.0 | H175: https://cdn2-retail-images.kiotviet.vn/giabaopharma/62824fbd8dee4bb8976511b0af6da67d.png
A176: 64 | B176: KHÁNG HISTAMIN - DỊ ỨNG | C176: SP648482 | D176: (Date 11/2026) Cetirizin cetirizine Boston (H/ 10 vỉ x 10 viên) ( CETI BOS ) | F176: 38,000.0 | G176: 44.0 | H176: https://cdn2-retail-images.kiotviet.vn/giabaopharma/6af0d69637db48249416a256798d55f4.jpg,https://cdn2-retail-images.kiotviet.vn/giabaopharma/5bb9a4f8561b44039bd0a2cf41c63711.jpg,https://cdn2-retail-images.kiotviet.vn/giabaopharma/1d055a11c8ba4428b0e1f3a53be56b73.jpg,https://cdn2-retail-images.kiotviet.vn/giabaopharma/cb86ee0db2664d8aa953bf6986bec88c.jpg,https://cdn2-retail-images.kiotviet.vn/giabaopharma/796f18864e634a09b69f0782f48ec73f.jpg
A177: 281 | B177: KHÁNG HISTAMIN - DỊ ỨNG | C177: Q302071123 | D177: Pacifdine Loratadine Tablets USP 10mg Baroque Ấn Độ (Hộp 10 vỉ x 10 viên nén) ( LORA 2 ) | F177: 23,500.0 | G177: 0.0 | H177: https://cdn-images.kiotviet.vn/giabaopharma/cb95607d9556427f8bfd055e791b0863.png,https://cdn-images.kiotviet.vn/giabaopharma/fdd25faef33b4e6693076532c248595c.png,https://cdn-images.kiotviet.vn/giabaopharma/c86b6a8640f54d259d018129cf059d22.png,https://cdn-images.kiotviet.vn/giabaopharma/5c12f7d7cb7f4ecc8193ed992eab010b.png,https://cdn-images.kiotviet.vn/giabaopharma/fb43c9818fa3452184d8a148142493d6.png
A178: 469 | B178: KHÁNG HISTAMIN - DỊ ỨNG | C178: Q302003356 | D178: (DateT3/25) Sagades Desloratadine Tablets 5mg Ấn Độ (Cọc 5 hộp - hộp 3 vỉ x 10 viên) ( DESLORA 2 ) | F178: 70,000.0 | G178: 0.0 | H178: https://product.hstatic.net/200000428801/product/05c4a991bfb148eaaf842a3d1917ef25_11429232e6c44ded9080c3863fee7f87.png
...
